2018-11-26 09:43:23.404155
softwaredownload
--
https://legacy.gitbook.com/@softwaredownload/starred?q=
--
404

2018-11-26 09:43:23.855986
softwaredownload
--
https://legacy.gitbook.com/@softwaredownload?q=
--
404

2018-11-26 09:43:38.415199
theiotlearninginitiative
--
https://legacy.gitbook.com/@theiotlearninginitiative/starred?q=
--
302

2018-11-26 09:43:39.707782
theiotlearninginitiative
--
https://legacy.gitbook.com/@theiotlearninginitiative?q=
--
302

2018-11-26 09:43:42.666885
learning-rust
--
https://legacy.gitbook.com/@learning-rust/starred?q=
--
302

2018-11-26 09:43:43.860784
learning-rust
--
https://legacy.gitbook.com/@learning-rust?q=
--
302

2018-11-26 09:43:45.742447
devops-collective-inc
--
https://legacy.gitbook.com/@devops-collective-inc/starred?q=
--
302

2018-11-26 09:43:47.159271
devops-collective-inc
--
https://legacy.gitbook.com/@devops-collective-inc?q=
--
302

2018-11-26 09:43:47.786187
json0071
--
https://legacy.gitbook.com/@json0071?q=
--
Traceback (most recent call last):
  File "/Users/vincent/PyEnv/gotbook_py3/lib/python3.7/site-packages/urllib3/connection.py", line 159, in _new_conn
    (self._dns_host, self.port), self.timeout, **extra_kw)
  File "/Users/vincent/PyEnv/gotbook_py3/lib/python3.7/site-packages/urllib3/util/connection.py", line 57, in create_connection
    for res in socket.getaddrinfo(host, port, family, socket.SOCK_STREAM):
  File "/usr/local/Cellar/python/3.7.1/Frameworks/Python.framework/Versions/3.7/lib/python3.7/socket.py", line 748, in getaddrinfo
    for res in _socket.getaddrinfo(host, port, family, type, proto, flags):
socket.gaierror: [Errno 8] nodename nor servname provided, or not known

During handling of the above exception, another exception occurred:

Traceback (most recent call last):
  File "/Users/vincent/PyEnv/gotbook_py3/lib/python3.7/site-packages/urllib3/connectionpool.py", line 600, in urlopen
    chunked=chunked)
  File "/Users/vincent/PyEnv/gotbook_py3/lib/python3.7/site-packages/urllib3/connectionpool.py", line 343, in _make_request
    self._validate_conn(conn)
  File "/Users/vincent/PyEnv/gotbook_py3/lib/python3.7/site-packages/urllib3/connectionpool.py", line 839, in _validate_conn
    conn.connect()
  File "/Users/vincent/PyEnv/gotbook_py3/lib/python3.7/site-packages/urllib3/connection.py", line 301, in connect
    conn = self._new_conn()
  File "/Users/vincent/PyEnv/gotbook_py3/lib/python3.7/site-packages/urllib3/connection.py", line 168, in _new_conn
    self, "Failed to establish a new connection: %s" % e)
urllib3.exceptions.NewConnectionError: <urllib3.connection.VerifiedHTTPSConnection object at 0x10df796a0>: Failed to establish a new connection: [Errno 8] nodename nor servname provided, or not known

During handling of the above exception, another exception occurred:

Traceback (most recent call last):
  File "/Users/vincent/PyEnv/gotbook_py3/lib/python3.7/site-packages/requests/adapters.py", line 449, in send
    timeout=timeout
  File "/Users/vincent/PyEnv/gotbook_py3/lib/python3.7/site-packages/urllib3/connectionpool.py", line 638, in urlopen
    _stacktrace=sys.exc_info()[2])
  File "/Users/vincent/PyEnv/gotbook_py3/lib/python3.7/site-packages/urllib3/util/retry.py", line 398, in increment
    raise MaxRetryError(_pool, url, error or ResponseError(cause))
urllib3.exceptions.MaxRetryError: HTTPSConnectionPool(host='legacy.gitbook.com', port=443): Max retries exceeded with url: /@json0071?q= (Caused by NewConnectionError('<urllib3.connection.VerifiedHTTPSConnection object at 0x10df796a0>: Failed to establish a new connection: [Errno 8] nodename nor servname provided, or not known'))

During handling of the above exception, another exception occurred:

Traceback (most recent call last):
  File "scanner.py", line 144, in scan_author
    res = requests.get(url, headers={'x-pjax': 'true', 'accept': '*/*'}, verify=False, timeout=10, allow_redirects=False)
  File "/Users/vincent/PyEnv/gotbook_py3/lib/python3.7/site-packages/requests/api.py", line 75, in get
    return request('get', url, params=params, **kwargs)
  File "/Users/vincent/PyEnv/gotbook_py3/lib/python3.7/site-packages/requests/api.py", line 60, in request
    return session.request(method=method, url=url, **kwargs)
  File "/Users/vincent/PyEnv/gotbook_py3/lib/python3.7/site-packages/requests/sessions.py", line 533, in request
    resp = self.send(prep, **send_kwargs)
  File "/Users/vincent/PyEnv/gotbook_py3/lib/python3.7/site-packages/requests/sessions.py", line 646, in send
    r = adapter.send(request, **kwargs)
  File "/Users/vincent/PyEnv/gotbook_py3/lib/python3.7/site-packages/requests/adapters.py", line 516, in send
    raise ConnectionError(e, request=request)
requests.exceptions.ConnectionError: HTTPSConnectionPool(host='legacy.gitbook.com', port=443): Max retries exceeded with url: /@json0071?q= (Caused by NewConnectionError('<urllib3.connection.VerifiedHTTPSConnection object at 0x10df796a0>: Failed to establish a new connection: [Errno 8] nodename nor servname provided, or not known'))

2018-11-26 09:43:51.111617
doczhcn
--
https://legacy.gitbook.com/@doczhcn/starred?q=
--
302

2018-11-26 09:43:52.115038
doczhcn
--
https://legacy.gitbook.com/@doczhcn?q=
--
302

2018-11-26 09:44:01.889303
gcpug-tw
--
https://legacy.gitbook.com/@gcpug-tw/starred?q=
--
302

2018-11-26 09:44:03.052031
gcpug-tw
--
https://legacy.gitbook.com/@gcpug-tw?q=
--
302

